<?xml version="1.0" ?>
<robot name="cart_pendulum">
  <link name="base_mount_manipulator_1">
    <visual name="base_mount_manipulator_1_visual">
      <origin xyz="0 0 0" rpy="0 0 0"/>
      <geometry>
        <mesh filename="meshes/base_mount_manipulator_1.stl"/>
      </geometry>
      <material name="base_mount_manipulator_1-material">
        <color rgba="0 0 1 1"/>
      </material>
    </visual>
    <collision name="base_mount_manipulator_1_collision">
      <origin xyz="0 0 0" rpy="0 0 0"/>
      <geometry>
        <mesh filename="meshes/base_mount_manipulator_1.stl"/>
      </geometry>
    </collision>
    <inertial>
      <mass value="542.6962"/>
      <inertia ixx="58.266937" iyy="58.266937" izz="5.6241518" ixy="-1.0064242e-16" ixz="4.109068e-16" iyz="2.0282611e-15"/>
      <origin xyz="0 0 0" rpy="0 0 0"/>
    </inertial>
  </link>
  <link name="link1_1">
    <visual name="link1_1_visual">
      <origin xyz="0 0 0" rpy="0 0 0"/>
      <geometry>
        <mesh filename="meshes/link1_1.stl"/>
      </geometry>
      <material name="link1_1-material">
        <color rgba="0 0 0 1"/>
      </material>
    </visual>
    <collision name="link1_1_collision">
      <origin xyz="0 0 0" rpy="0 0 0"/>
      <geometry>
        <mesh filename="meshes/link1_1.stl"/>
      </geometry>
    </collision>
    <inertial>
      <mass value="10.815255"/>
      <inertia ixx="0.012898837" iyy="0.98114122" izz="0.98350523" ixy="0" ixz="-0.026659751" iyz="0"/>
      <origin xyz="-0.54922481 -5.4256962e-18 -0.025167416" rpy="0 0 0"/>
    </inertial>
  </link>
  <link name="mount_rail_2_1">
    <visual name="mount_rail_2_1_visual">
      <origin xyz="0 0 0" rpy="0 0 0"/>
      <geometry>
        <mesh filename="meshes/mount_rail_2_1.stl"/>
      </geometry>
      <material name="mount_rail_2_1-material">
        <color rgba="0 0 1 1"/>
      </material>
    </visual>
    <collision name="mount_rail_2_1_collision">
      <origin xyz="0 0 0" rpy="0 0 0"/>
      <geometry>
        <mesh filename="meshes/mount_rail_2_1.stl"/>
      </geometry>
    </collision>
    <inertial>
      <mass value="487.68125"/>
      <inertia ixx="42.721446" iyy="5.0806999" izz="42.722133" ixy="1.535218e-16" ixz="1.1040928e-15" iyz="0"/>
      <origin xyz="-1.0015279e-16 -0.49705734 0.125" rpy="0 0 0"/>
    </inertial>
  </link>
  <link name="link2_1">
    <visual name="link2_1_visual">
      <origin xyz="0 0 0" rpy="0 0 0"/>
      <geometry>
        <mesh filename="meshes/link2_1.stl"/>
      </geometry>
      <material name="link2_1-material">
        <color rgba="1 0.5 0 1"/>
      </material>
    </visual>
    <collision name="link2_1_collision">
      <origin xyz="0 0 0" rpy="0 0 0"/>
      <geometry>
        <mesh filename="meshes/link2_1.stl"/>
      </geometry>
    </collision>
    <inertial>
      <mass value="9.6973507"/>
      <inertia ixx="0.00835887" iyy="0.77333393" izz="0.77934359" ixy="0" ixz="0" iyz="0"/>
      <origin xyz="-0.50267787 -1.1327507e-17 -0.0190625" rpy="0 0 0"/>
    </inertial>
  </link>
  <link name="rail_2_1">
    <visual name="rail_2_1_visual">
      <origin xyz="0 0 0" rpy="0 0 0"/>
      <geometry>
        <mesh filename="meshes/rail_2_1.stl"/>
      </geometry>
      <material name="rail_2_1-material">
        <color rgba="1 1 1 1"/>
      </material>
    </visual>
    <collision name="rail_2_1_collision">
      <origin xyz="0 0 0" rpy="0 0 0"/>
      <geometry>
        <mesh filename="meshes/rail_2_1.stl"/>
      </geometry>
    </collision>
    <inertial>
      <mass value="4.08"/>
      <inertia ixx="0.0005185" iyy="1.3602125" izz="1.360306" ixy="0" ixz="0" iyz="0"/>
      <origin xyz="-1 -0.015 1.110223e-16" rpy="0 0 0"/>
    </inertial>
  </link>
  <link name="rail_1_1">
    <visual name="rail_1_1_visual">
      <origin xyz="0 0 0" rpy="0 0 0"/>
      <geometry>
        <mesh filename="meshes/rail_1_1.stl"/>
      </geometry>
      <material name="rail_1_1-material">
        <color rgba="0 0 1 1"/>
      </material>
    </visual>
    <collision name="rail_1_1_collision">
      <origin xyz="0 0 0" rpy="0 0 0"/>
      <geometry>
        <mesh filename="meshes/rail_1_1.stl"/>
      </geometry>
    </collision>
    <inertial>
      <mass value="4.08"/>
      <inertia ixx="0.0005185" iyy="1.360306" izz="1.3602125" ixy="0" ixz="0" iyz="0"/>
      <origin xyz="-1 -1.110223e-16 -0.015" rpy="0 0 0"/>
    </inertial>
  </link>
  <link name="mount_rail_1_1">
    <visual name="mount_rail_1_1_visual">
      <origin xyz="0 0 0" rpy="0 0 0"/>
      <geometry>
        <mesh filename="meshes/mount_rail_1_1.stl"/>
      </geometry>
      <material name="mount_rail_1_1-material">
        <color rgba="1 0 1 1"/>
      </material>
    </visual>
    <collision name="mount_rail_1_1_collision">
      <origin xyz="0 0 0" rpy="0 0 0"/>
      <geometry>
        <mesh filename="meshes/mount_rail_1_1.stl"/>
      </geometry>
    </collision>
    <inertial>
      <mass value="487.68125"/>
      <inertia ixx="42.721446" iyy="5.0806999" izz="42.722133" ixy="1.1160302e-16" ixz="-7.9774712e-16" iyz="0"/>
      <origin xyz="0.07 0.47794266 -0.125" rpy="0 0 0"/>
    </inertial>
  </link>
  <link name="cart_1">
    <visual name="cart_1_visual">
      <origin xyz="0 0 0" rpy="0 0 0"/>
      <geometry>
        <mesh filename="meshes/cart_1.stl"/>
      </geometry>
      <material name="cart_1-material">
        <color rgba="0 0 0 1"/>
      </material>
    </visual>
    <collision name="cart_1_collision">
      <origin xyz="0 0 0" rpy="0 0 0"/>
      <geometry>
        <mesh filename="meshes/cart_1.stl"/>
      </geometry>
    </collision>
    <inertial>
      <mass value="1.3341545"/>
      <inertia ixx="0.009385059" iyy="0.01156555" izz="0.009245384" ixy="0" ixz="0" iyz="0"/>
      <origin xyz="0.07 -0.013772027 -0.1" rpy="0 0 0"/>
    </inertial>
  </link>
  <link name="Pendulum_1">
    <visual name="Pendulum_1_visual">
      <origin xyz="0 0 0" rpy="0 0 0"/>
      <geometry>
        <mesh filename="meshes/Pendulum_1.stl"/>
      </geometry>
      <material name="Pendulum_1-material">
        <color rgba="0 1 1 1"/>
      </material>
    </visual>
    <collision name="Pendulum_1_collision">
      <origin xyz="0 0 0" rpy="0 0 0"/>
      <geometry>
        <mesh filename="meshes/Pendulum_1.stl"/>
      </geometry>
    </collision>
    <inertial>
      <mass value="0.044497704"/>
      <inertia ixx="0.0018033039" iyy="1.5292824e-05" izz="0.0017893983" ixy="7.5381068e-10" ixz="-4.0780507e-11" iyz="9.5148226e-05"/>
      <origin xyz="-1.2577758e-07 0.17136626 -0.04552224" rpy="0 0 0"/>
    </inertial>
  </link>
  <link name="Pendulum_bob_1">
    <visual name="Pendulum_bob_1_visual">
      <origin xyz="0 0 0" rpy="0 0 0"/>
      <geometry>
        <mesh filename="meshes/Pendulum_bob_1.stl"/>
      </geometry>
      <material name="Pendulum_bob_1-material">
        <color rgba="0 1 1 1"/>
      </material>
    </visual>
    <collision name="Pendulum_bob_1_collision">
      <origin xyz="0 0 0" rpy="0 0 0"/>
      <geometry>
        <mesh filename="meshes/Pendulum_bob_1.stl"/>
      </geometry>
    </collision>
    <inertial>
      <mass value="4.4453536"/>
      <inertia ixx="0.0044453536" iyy="0.0044453536" izz="0.0044453536" ixy="0" ixz="0" iyz="0"/>
      <origin xyz="0 0 0" rpy="0 0 0"/>
    </inertial>
  </link>
  <joint name="dof_jt_mount_link1" type="revolute">
    <origin xyz="4.3631354e-19 -2.2265976e-17 0.62298944" rpy="0 0 0"/>
    <parent link="base_mount_manipulator_1"/>
    <child link="link1_1"/>
    <axis xyz="0 0 -1"/>
    <limit effort="1" velocity="1" lower="-6.2831853" upper="6.2831853"/>
  </joint>
  <joint name="Fastened_1" type="fixed">
    <origin xyz="-0.125 3.0403059e-18 -0.55326056" rpy="-1.5707963 0 1.5707963"/>
    <parent link="base_mount_manipulator_1"/>
    <child link="mount_rail_2_1"/>
  </joint>
  <joint name="dof_jt_link1_link2" type="revolute">
    <origin xyz="-0.953 -4.8985872e-18 -0.118125" rpy="3.1415927 0 0"/>
    <parent link="link1_1"/>
    <child link="link2_1"/>
    <axis xyz="0 0 -1"/>
    <limit effort="1" velocity="1" lower="-6.2831853" upper="6.2831853"/>
  </joint>
  <joint name="Fastened_2" type="fixed">
    <origin xyz="-0.055 -0.9875 0" rpy="1.5707963 1.5707963 0"/>
    <parent link="mount_rail_2_1"/>
    <child link="rail_2_1"/>
  </joint>
  <joint name="Fastened_3" type="fixed">
    <origin xyz="0.085 -0.9875 0" rpy="-0 1.5707963 0"/>
    <parent link="mount_rail_2_1"/>
    <child link="rail_1_1"/>
  </joint>
  <joint name="Fastened_4" type="fixed">
    <origin xyz="-2 -0.015 -0.0125" rpy="-1.5707963 0 1.5707963"/>
    <parent link="rail_2_1"/>
    <child link="mount_rail_1_1"/>
  </joint>
  <joint name="dof_jt_rail_cart" type="prismatic">
    <origin xyz="-2 -0.015 0.0125" rpy="-1.5707963 0 1.5707963"/>
    <parent link="rail_2_1"/>
    <child link="cart_1"/>
    <axis xyz="0 0 -1"/>
    <limit effort="1" velocity="1" lower="-0.1" upper="0.1"/>
  </joint>
  <joint name="dof_jt_cart_pendulum" type="revolute">
    <origin xyz="0.085 0.0594 -0.1" rpy="-0 1.5707963 0"/>
    <parent link="cart_1"/>
    <child link="Pendulum_1"/>
    <axis xyz="0 0 -1"/>
    <limit effort="1" velocity="1" lower="-6.2831853" upper="6.2831853"/>
  </joint>
  <joint name="Fastened_5" type="fixed">
    <origin xyz="9.7144515e-17 0.60866025 -0.058" rpy="1.5707963 0 0"/>
    <parent link="Pendulum_1"/>
    <child link="Pendulum_bob_1"/>
  </joint>
</robot>
